Workbook

Sheet Market
A1: Id | B1: Mat | C1: Price | E1: Id | F1: Potion | G1: Price | I1: Id | J1: Resource | K1: Market price | M1: Id | N1: Recipe | O1: Price | P1: Value | Q1: Chance
B2: Moose antler | C2: 125 | F2: Wraithbane | G2: 11600 | J2: Coal | K2: 6 | N2: Improved Fishing Rod Recipe | O2: 300 | Q2: 0.05
B3: Minotaur Hide | C3: 413 | F3: Thunderfury | G3: 5500 | J3: Stingray | K3: 38 | N3: Improved Pickaxe Recipe | O3: 1600 | Q3: 0.05
B4: Black Bear Pelt | C4: 82 | F4: Gourmet | G4: 7150 | J4: Cooked Stingray | K4: 67 | N4: Improved Felling axe Recipe | O4: 250 | Q4: 0.05
B5: Orb of elemental | C5: 105 | F5: Dungeon master | G5: 2291 | J5: White shark | K5: 56 | N5: Herculean Strength Elixir Recipe | O5: 28 | Q5: =0.2*0.25 -> 0.05
B6: Elk Antler | C6: 335 | F6: Frenzy | G6: 3100 | J6: Cooked White Shark | K6: 105 | N6: Bastion Elixir Recipe | O6: 19 | Q6: =0.2*0.25 -> 0.05
B7: Enigmatic Stone | C7: 50 | F7: Cosmic | G7: 5900 | J7: Mystic Ore | K7: 24 | N7: Galeforce Speed Elixir Recipe | O7: 29 | Q7: =0.2*0.25 -> 0.05
B8: Lions teeth | C8: 160 | J8: Mystic Bar | K8: 67 | N8: Falcon's Grace Elixir Recipe | O8: 17 | Q8: =0.2*0.25 -> 0.05
B9: Wolf pelt | C9: 96 | N9: Rivertamer Recipe | O9: 650 | Q9: 0.05
B10: Goblin totem | C10: 37 | N10: Veinseeker Recipe | O10: 6200 | Q10: 0.05
B11: Harpy wing | C11: 14 | N11: Timberfall Talon Recipe | O11: 850 | Q11: 0.05
B12: Air elemental | C12: 290 | N12: Protection Potion Recipe | O12: 145 | Q12: =0.3*0.17 -> 0.051
N13: Felling Essence Recipe | O13: 44 | Q13: =0.3*0.17 -> 0.051
N14: Oreseeker Essence Crystal Recipe | O14: 64 | Q14: =0.3*0.17 -> 0.051
N15: Attack Power Potion Recipe | O15: 42 | Q15: =0.3*0.17 -> 0.051
N16: Titan Power Brew Recipe | O16: 78 | Q16: =0.3*0.17 -> 0.051
N17: Vortex Brew Recipe | O17: 135 | Q17: =0.3*0.15 -> 0.045
N18: Seasong's Lure Recipe | O18: 2900 | Q18: 0.05
N19: Ironbite Recipe | O19: 14000 | Q19: 0.05
N20: Wildwood Chopper Recipe | O20: 1690 | Q20: 0.05
N21: Fortified Protection Recipe | O21: 228 | Q21: =0.35*0.13 -> 0.0455
N22: Quickstep Essence Recipe | O22: 94 | Q22: =0.35*0.13 -> 0.0455
N23: Precision Essence Recipe | O23: 88 | Q23: =0.35*0.13 -> 0.0455
N24: Merfolk Essence Recipe | O24: 555 | Q24: =0.35*0.13 -> 0.0455
N25: Molten Core Tonic Recipe | O25: 500 | Q25: =0.35*0.12 -> 0.042
N26: Spicefinder Essence Crystal Recipe | O26: 404 | Q26: =0.35*0.1 -> 0.035
N27: Bulwark Brew Recipe | O27: 295 | Q27: =0.35*0.1 -> 0.035
N28: Bladeburst Elixir Recipe | O28: 199 | Q28: =0.35*0.1 -> 0.035
N29: Ironclad Tonic Recipe | O29: 244 | Q29: =0.35*0.1 -> 0.035
N30: Moonshimmer Hook Recipe | O30: 15000 | Q30: 0.05
N31: Boulder Breaker Recipe | O31: 33000 | Q31: 0.05
N32: Leafblade Recipe | O32: 5998 | Q32: 0.05
N33: Impenetrable Essence Recipe | O33: 117 | Q33: =0.26*0.18 -> 0.0468
N34: Windrider Essence Recipe | O34: 119 | Q34: =0.26*0.18 -> 0.0468
N35: Acrobatic's Essence Recipe | O35: 130 | Q35: =0.26*0.18 -> 0.0468
N36: Strike Essence Recipe | O36: 137 | Q36: =0.26*0.18 -> 0.0468
N37: Yggdrasil Nectar Recipe | O37: 120 | Q37: =0.26*0.18 -> 0.0468
N38: Earthcore Infusion Recipe | O38: 549 | Q38: =0.26*0.1 -> 0.026
N39: Shadowbane Recipe | O39: 1444 | Q39: =R39/100 -> 0.02 | R39: 2
N40: Soulrender Recipe | O40: 1690 | Q40: =R40/100 -> 0.019 | R40: 1.9
...

Sheet Dungeon
A1: Dungeon | B1: Offset | C1: Run cost | D1: Time | E1: Profit | F1: Profit/h | G1: Number of drops | H1: Drop1 | I1: Drop1 Price | J1: Drop2 | K1: Drop2 Price | L1: Drop3 | M1: Drop3 Price | N1: Drop4 | O1: Drop4 Price | P1: Drop5 | Q1: Drop5 Price | R1: Drop6 | S1: Drop6 Price | T1: Drop7 | U1: Drop7 Price | V1: Drop8 | W1: Drop8 Price | X1: Drop9 | Y1: Drop9 Price | Z1: Drop10 | AA1: Drop10 Price | AB1: Drop11 | AC1: Drop11 Price | AD1: Drop12 | AE1: Drop12 Price | AF1: Drop13 | AG1: Drop13 Price | AH1: Drop14 | AI1: Drop14 Price | AJ1: Drop15 | AK1: Drop15 Price | AL1: Drop16 | AM1: Drop16 Price | AN1: Drop17 | AO1: Drop17 Price | AP1: Drop18 | AQ1: Drop18 Price | AR1: Drop19 | AS1: Drop19 Price | AT1: Drop20 | AU1: Drop20 Price | AV1: Drop21 | AW1: Drop21 Price | AX1: Drop22 | AY1: Drop22 Price | AZ1: Drop23 | BA1: Drop23 Price | BB1: Drop24 | BC1: Drop24 Price | BD1: Drop25 | BE1: Drop25 Price | BF1: Drop26 | BG1: Drop26 Price | BH1: Drop27 | BI1: Drop27 Price | BJ1: Drop28 | BK1: Drop28 Price | BL1: Drop29 | BM1: Drop29 Price | BN1: Drop30 | BO1: Drop30 Price
A2: Millstone Mines | B2: 1 | C2: 300 | D2: 7200 | E2: =SUM(H2:ABF2)-C2 -> -147.476 | F2: =E2/(D2/3600) -> -73.738 | G2: 7 | H2: =IFERROR(__xludf.DUMMYFUNCTION("MAP(OFFSET($H$1,0,0,1,G2*2),LAMBDA(c,IF(ISEVEN(COLUMN(c)),INDIRECT(ADDRESS(REGEXEXTRACT(c,""\d+"")+$B2,14,1,TRUE,""Market"")),INDIRECT(ADDRESS(REGEXEXTRACT(c,""\d+"")+$B2,15,3,,""Market""))*(INDIRECT(ADDRESS(REGEXEXTRACT(c,""\d+"")+$B2,17,3,,""Market""))*"&"(1+$B$27/100)))))"),"Improved Fishing Rod Recipe") -> Improved Fishing Rod Recipe | I2: =IFERROR(__xludf.DUMMYFUNCTION("""COMPUTED_VALUE"""),20.4) -> 20.4 | J2: =IFERROR(__xludf.DUMMYFUNCTION("""COMPUTED_VALUE"""),"Improved Pickaxe Recipe ") -> Improved Pickaxe Recipe | K2: =IFERROR(__xludf.DUMMYFUNCTION("""COMPUTED_VALUE"""),108.79999999999998) -> 108.8 | L2: =IFERROR(__xludf.DUMMYFUNCTION("""COMPUTED_VALUE"""),"Improved Felling axe Recipe ") -> Improved Felling axe Recipe | M2: =IFERROR(__xludf.DUMMYFUNCTION("""COMPUTED_VALUE"""),16.999999999999996) -> 17 | N2: =IFERROR(__xludf.DUMMYFUNCTION("""COMPUTED_VALUE"""),"Herculean Strength Elixir Recipe ") -> Herculean Strength Elixir Recipe | O2: =IFERROR(__xludf.DUMMYFUNCTION("""COMPUTED_VALUE"""),1.9039999999999997) -> 1.904 | P2: =IFERROR(__xludf.DUMMYFUNCTION("""COMPUTED_VALUE"""),"Bastion Elixir Recipe ") -> Bastion Elixir Recipe | Q2: =IFERROR(__xludf.DUMMYFUNCTION("""COMPUTED_VALUE"""),1.2919999999999998) -> 1.292 | R2: =IFERROR(__xludf.DUMMYFUNCTION("""COMPUTED_VALUE"""),"Galeforce Speed Elixir Recipe ") -> Galeforce Speed Elixir Recipe | S2: =IFERROR(__xludf.DUMMYFUNCTION("""COMPUTED_VALUE"""),1.9719999999999998) -> 1.972 | T2: =IFERROR(__xludf.DUMMYFUNCTION("""COMPUTED_VALUE"""),"Falcon's Grace Elixir Recipe ") -> Falcon's Grace Elixir Recipe | U2: =IFERROR(__xludf.DUMMYFUNCTION("""COMPUTED_VALUE"""),1.156) -> 1.156
A3: Vineyard Labyrinth | B3: =B2+G2 -> 8 | C3: 1200 | D3: =2*3600+3*60+20 -> 7400 | E3: =SUM(H3:ABF3)-C3 -> -642.26672 | F3: =E3/(D3/3600) -> -312.45408 | G3: 9 | H3: =IFERROR(__xludf.DUMMYFUNCTION("MAP(OFFSET($H$1,0,0,1,G3*2),LAMBDA(c,IF(ISEVEN(COLUMN(c)),INDIRECT(ADDRESS(REGEXEXTRACT(c,""\d+"")+$B3,14,1,TRUE,""Market"")),INDIRECT(ADDRESS(REGEXEXTRACT(c,""\d+"")+$B3,15,3,,""Market""))*(INDIRECT(ADDRESS(REGEXEXTRACT(c,""\d+"")+$B3,17,3,,""Market""))*"&"(1+$B$27/100)))))"),"Rivertamer Recipe ") -> Rivertamer Recipe | I3: =IFERROR(__xludf.DUMMYFUNCTION("""COMPUTED_VALUE"""),44.199999999999996) -> 44.2 | J3: =IFERROR(__xludf.DUMMYFUNCTION("""COMPUTED_VALUE"""),"Veinseeker Recipe") -> Veinseeker Recipe | K3: =IFERROR(__xludf.DUMMYFUNCTION("""COMPUTED_VALUE"""),421.59999999999997) -> 421.6 | L3: =IFERROR(__xludf.DUMMYFUNCTION("""COMPUTED_VALUE"""),"Timberfall Talon Recipe ") -> Timberfall Talon Recipe | M3: =IFERROR(__xludf.DUMMYFUNCTION("""COMPUTED_VALUE"""),57.79999999999999) -> 57.8 | N3: =IFERROR(__xludf.DUMMYFUNCTION("""COMPUTED_VALUE"""),"Protection Potion Recipe ") -> Protection Potion Recipe | O3: =IFERROR(__xludf.DUMMYFUNCTION("""COMPUTED_VALUE"""),10.0572) -> 10.0572 | P3: =IFERROR(__xludf.DUMMYFUNCTION("""COMPUTED_VALUE"""),"Felling Essence Recipe ") -> Felling Essence Recipe | Q3: =IFERROR(__xludf.DUMMYFUNCTION("""COMPUTED_VALUE"""),3.0518400000000003) -> 3.05184 | R3: =IFERROR(__xludf.DUMMYFUNCTION("""COMPUTED_VALUE"""),"Oreseeker Essence Crystal Recipe ") -> Oreseeker Essence Crystal Recipe | S3: =IFERROR(__xludf.DUMMYFUNCTION("""COMPUTED_VALUE"""),4.43904) -> 4.43904 | T3: =IFERROR(__xludf.DUMMYFUNCTION("""COMPUTED_VALUE"""),"Attack Power Potion Recipe ") -> Attack Power Potion Recipe | U3: =IFERROR(__xludf.DUMMYFUNCTION("""COMPUTED_VALUE"""),2.91312) -> 2.91312 | V3: =IFERROR(__xludf.DUMMYFUNCTION("""COMPUTED_VALUE"""),"Titan Power Brew Recipe") -> Titan Power Brew Recipe | W3: =IFERROR(__xludf.DUMMYFUNCTION("""COMPUTED_VALUE"""),5.410080000000001) -> 5.41008 | X3: =IFERROR(__xludf.DUMMYFUNCTION("""COMPUTED_VALUE"""),"Vortex Brew Recipe ") -> Vortex Brew Recipe | Y3: =IFERROR(__xludf.DUMMYFUNCTION("""COMPUTED_VALUE"""),8.261999999999999) -> 8.262
A4: Verdant Veil | B4: =B3+G3 -> 17 | C4: 2400 | D4: =2*3600+6*60+40 -> 7600 | E4: =SUM(H4:ABF4)-C4 -> -993.2466 | F4: =E4/(D4/3600) -> -470.48523 | G4: 12 | H4: =IFERROR(__xludf.DUMMYFUNCTION("MAP(OFFSET($H$1,0,0,1,G4*2),LAMBDA(c,IF(ISEVEN(COLUMN(c)),INDIRECT(ADDRESS(REGEXEXTRACT(c,""\d+"")+$B4,14,1,TRUE,""Market"")),INDIRECT(ADDRESS(REGEXEXTRACT(c,""\d+"")+$B4,15,3,,""Market""))*(INDIRECT(ADDRESS(REGEXEXTRACT(c,""\d+"")+$B4,17,3,,""Market""))*"&"(1+$B$27/100)))))"),"Seasong's Lure Recipe ") -> Seasong's Lure Recipe | I4: =IFERROR(__xludf.DUMMYFUNCTION("""COMPUTED_VALUE"""),197.19999999999996) -> 197.2 | J4: =IFERROR(__xludf.DUMMYFUNCTION("""COMPUTED_VALUE"""),"Ironbite Recipe") -> Ironbite Recipe | K4: =IFERROR(__xludf.DUMMYFUNCTION("""COMPUTED_VALUE"""),951.9999999999999) -> 952 | L4: =IFERROR(__xludf.DUMMYFUNCTION("""COMPUTED_VALUE"""),"Wildwood Chopper Recipe") -> Wildwood Chopper Recipe | M4: =IFERROR(__xludf.DUMMYFUNCTION("""COMPUTED_VALUE"""),114.91999999999999) -> 114.92 | N4: =IFERROR(__xludf.DUMMYFUNCTION("""COMPUTED_VALUE"""),"Fortified Protection Recipe") -> Fortified Protection Recipe | O4: =IFERROR(__xludf.DUMMYFUNCTION("""COMPUTED_VALUE"""),14.108639999999998) -> 14.10864 | P4: =IFERROR(__xludf.DUMMYFUNCTION("""COMPUTED_VALUE"""),"Quickstep Essence Recipe") -> Quickstep Essence Recipe | Q4: =IFERROR(__xludf.DUMMYFUNCTION("""COMPUTED_VALUE"""),5.816719999999999) -> 5.81672 | R4: =IFERROR(__xludf.DUMMYFUNCTION("""COMPUTED_VALUE"""),"Precision Essence Recipe") -> Precision Essence Recipe | S4: =IFERROR(__xludf.DUMMYFUNCTION("""COMPUTED_VALUE"""),5.44544) -> 5.44544 | T4: =IFERROR(__xludf.DUMMYFUNCTION("""COMPUTED_VALUE"""),"Merfolk Essence Recipe") -> Merfolk Essence Recipe | U4: =IFERROR(__xludf.DUMMYFUNCTION("""COMPUTED_VALUE"""),34.343399999999995) -> 34.3434 | V4: =IFERROR(__xludf.DUMMYFUNCTION("""COMPUTED_VALUE"""),"Molten Core Tonic Recipe") -> Molten Core Tonic Recipe | W4: =IFERROR(__xludf.DUMMYFUNCTION("""COMPUTED_VALUE"""),28.559999999999995) -> 28.56 | X4: =IFERROR(__xludf.DUMMYFUNCTION("""COMPUTED_VALUE"""),"Spicefinder Essence Crystal Recipe") -> Spicefinder Essence Crystal Recipe | Y4: =IFERROR(__xludf.DUMMYFUNCTION("""COMPUTED_VALUE"""),19.230399999999996) -> 19.2304 | Z4: =IFERROR(__xludf.DUMMYFUNCTION("""COMPUTED_VALUE"""),"Bulwark Brew Recipe") -> Bulwark Brew Recipe | AA4: =IFERROR(__xludf.DUMMYFUNCTION("""COMPUTED_VALUE"""),14.041999999999996) -> 14.042 | AB4: =IFERROR(__xludf.DUMMYFUNCTION("""COMPUTED_VALUE"""),"Bladeburst Elixir Recipe") -> Bladeburst Elixir Recipe | AC4: =IFERROR(__xludf.DUMMYFUNCTION("""COMPUTED_VALUE"""),9.472399999999999) -> 9.4724 | AD4: =IFERROR(__xludf.DUMMYFUNCTION("""COMPUTED_VALUE"""),"Ironclad Tonic Recipe") -> Ironclad Tonic Recipe | AE4: =IFERROR(__xludf.DUMMYFUNCTION("""COMPUTED_VALUE"""),11.614399999999998) -> 11.6144
A5: Sylvan Sanctum | B5: =B4+G4 -> 29 | C5: 3600 | D5: =2*3600+10*60 -> 7800 | E5: =SUM(H5:ABF5)-C5 -> 130.92934 | F5: =E5/(D5/3600) -> 60.428928 | G5: 9 | H5: =IFERROR(__xludf.DUMMYFUNCTION("MAP(OFFSET($H$1,0,0,1,G5*2),LAMBDA(c,IF(ISEVEN(COLUMN(c)),INDIRECT(ADDRESS(REGEXEXTRACT(c,""\d+"")+$B5,14,1,TRUE,""Market"")),INDIRECT(ADDRESS(REGEXEXTRACT(c,""\d+"")+$B5,15,3,,""Market""))*(INDIRECT(ADDRESS(REGEXEXTRACT(c,""\d+"")+$B5,17,3,,""Market""))*"&"(1+$B$27/100)))))"),"Moonshimmer Hook Recipe") -> Moonshimmer Hook Recipe | I5: =IFERROR(__xludf.DUMMYFUNCTION("""COMPUTED_VALUE"""),1019.9999999999999) -> 1020 | J5: =IFERROR(__xludf.DUMMYFUNCTION("""COMPUTED_VALUE"""),"Boulder Breaker Recipe") -> Boulder Breaker Recipe | K5: =IFERROR(__xludf.DUMMYFUNCTION("""COMPUTED_VALUE"""),2243.9999999999995) -> 2244 | L5: =IFERROR(__xludf.DUMMYFUNCTION("""COMPUTED_VALUE"""),"Leafblade Recipe") -> Leafblade Recipe | M5: =IFERROR(__xludf.DUMMYFUNCTION("""COMPUTED_VALUE"""),407.8639999999999) -> 407.864 | N5: =IFERROR(__xludf.DUMMYFUNCTION("""COMPUTED_VALUE"""),"Impenetrable Essence Recipe") -> Impenetrable Essence Recipe | O5: =IFERROR(__xludf.DUMMYFUNCTION("""COMPUTED_VALUE"""),7.446815999999999) -> 7.446816 | P5: =IFERROR(__xludf.DUMMYFUNCTION("""COMPUTED_VALUE"""),"Windrider Essence Recipe") -> Windrider Essence Recipe | Q5: =IFERROR(__xludf.DUMMYFUNCTION("""COMPUTED_VALUE"""),7.5741119999999995) -> 7.574112 | R5: =IFERROR(__xludf.DUMMYFUNCTION("""COMPUTED_VALUE"""),"Acrobatic's Essence Recipe") -> Acrobatic's Essence Recipe | S5: =IFERROR(__xludf.DUMMYFUNCTION("""COMPUTED_VALUE"""),8.274239999999999) -> 8.27424 | T5: =IFERROR(__xludf.DUMMYFUNCTION("""COMPUTED_VALUE"""),"Strike Essence Recipe") -> Strike Essence Recipe | U5: =IFERROR(__xludf.DUMMYFUNCTION("""COMPUTED_VALUE"""),8.719776) -> 8.719776 | V5: =IFERROR(__xludf.DUMMYFUNCTION("""COMPUTED_VALUE"""),"Yggdrasil Nectar Recipe") -> Yggdrasil Nectar Recipe | W5: =IFERROR(__xludf.DUMMYFUNCTION("""COMPUTED_VALUE"""),7.637759999999999) -> 7.63776 | X5: =IFERROR(__xludf.DUMMYFUNCTION("""COMPUTED_VALUE"""),"Earthcore Infusion Recipe") -> Earthcore Infusion Recipe | Y5: =IFERROR(__xludf.DUMMYFUNCTION("""COMPUTED_VALUE"""),19.41264) -> 19.41264
A6: Whispering Catacombs | B6: =B5+G5 -> 38 | C6: 5000 | D6: =2*3600+13*60+20 -> 8000 | E6: =SUM(H6:ABF6)-C6 -> -3220.3606 | F6: =E6/(D6/3600) -> -1449.1623 | G6: 20 | H6: =IFERROR(__xludf.DUMMYFUNCTION("MAP(OFFSET($H$1,0,0,1,G6*2),LAMBDA(c,IF(ISEVEN(COLUMN(c)),INDIRECT(ADDRESS(REGEXEXTRACT(c,""\d+"")+$B6,14,1,TRUE,""Market"")),INDIRECT(ADDRESS(REGEXEXTRACT(c,""\d+"")+$B6,15,3,,""Market""))*(INDIRECT(ADDRESS(REGEXEXTRACT(c,""\d+"")+$B6,17,3,,""Market""))*"&"(1+$B$27/100)))))"),"Shadowbane Recipe") -> Shadowbane Recipe | I6: =IFERROR(__xludf.DUMMYFUNCTION("""COMPUTED_VALUE"""),39.276799999999994) -> 39.2768 | J6: =IFERROR(__xludf.DUMMYFUNCTION("""COMPUTED_VALUE"""),"Soulrender Recipe") -> Soulrender Recipe | K6: =IFERROR(__xludf.DUMMYFUNCTION("""COMPUTED_VALUE"""),43.669599999999996) -> 43.6696 | L6: =IFERROR(__xludf.DUMMYFUNCTION("""COMPUTED_VALUE"""),"Shadowstrike Recipe") -> Shadowstrike Recipe | M6: =IFERROR(__xludf.DUMMYFUNCTION("""COMPUTED_VALUE"""),16.2928) -> 16.2928 | N6: =IFERROR(__xludf.DUMMYFUNCTION("""COMPUTED_VALUE"""),"Venomfang Recipe") -> Venomfang Recipe | O6: =IFERROR(__xludf.DUMMYFUNCTION("""COMPUTED_VALUE"""),15.2456) -> 15.2456 | P6: =IFERROR(__xludf.DUMMYFUNCTION("""COMPUTED_VALUE"""),"Whisperwind Bow Recipe") -> Whisperwind Bow Recipe | Q6: =IFERROR(__xludf.DUMMYFUNCTION("""COMPUTED_VALUE"""),24.208) -> 24.208 | R6: =IFERROR(__xludf.DUMMYFUNCTION("""COMPUTED_VALUE"""),"Stormcaster Recipe") -> Stormcaster Recipe | S6: =IFERROR(__xludf.DUMMYFUNCTION("""COMPUTED_VALUE"""),23.256) -> 23.256 | T6: =IFERROR(__xludf.DUMMYFUNCTION("""COMPUTED_VALUE"""),"Radiant Crest Recipe") -> Radiant Crest Recipe | U6: =IFERROR(__xludf.DUMMYFUNCTION("""COMPUTED_VALUE"""),40.7728) -> 40.7728 | V6: =IFERROR(__xludf.DUMMYFUNCTION("""COMPUTED_VALUE"""),"Shadow Helm Recipe") -> Shadow Helm Recipe | W6: =IFERROR(__xludf.DUMMYFUNCTION("""COMPUTED_VALUE"""),33.592) -> 33.592 | X6: =IFERROR(__xludf.DUMMYFUNCTION("""COMPUTED_VALUE"""),"Ironclad Gauntlets Recipe") -> Ironclad Gauntlets Recipe | Y6: =IFERROR(__xludf.DUMMYFUNCTION("""COMPUTED_VALUE"""),48.959999999999994) -> 48.96 | Z6: =IFERROR(__xludf.DUMMYFUNCTION("""COMPUTED_VALUE"""),"Stormguard Plate Recipe") -> Stormguard Plate Recipe | AA6: =IFERROR(__xludf.DUMMYFUNCTION("""COMPUTED_VALUE"""),24.4528) -> 24.4528 | AB6: =IFERROR(__xludf.DUMMYFUNCTION("""COMPUTED_VALUE"""),"Dragonheart Plate Recipe") -> Dragonheart Plate Recipe | AC6: =IFERROR(__xludf.DUMMYFUNCTION("""COMPUTED_VALUE"""),74.62592) -> 74.62592 | AD6: =IFERROR(__xludf.DUMMYFUNCTION("""COMPUTED_VALUE"""),"Stormstrider Greaves Recipe") -> Stormstrider Greaves Recipe | AE6: =IFERROR(__xludf.DUMMYFUNCTION("""COMPUTED_VALUE"""),85.67999999999999) -> 85.68 | AF6: =IFERROR(__xludf.DUMMYFUNCTION("""COMPUTED_VALUE"""),"Shadowstep Greaves Recipe") -> Shadowstep Greaves Recipe | AG6: =IFERROR(__xludf.DUMMYFUNCTION("""COMPUTED_VALUE"""),95.60799999999999) -> 95.608 | AH6: =IFERROR(__xludf.DUMMYFUNCTION("""COMPUTED_VALUE"""),"Swiftwind Boots Recipe") -> Swiftwind Boots Recipe | AI6: =IFERROR(__xludf.DUMMYFUNCTION("""COMPUTED_VALUE"""),32.6128) -> 32.6128 | AJ6: =IFERROR(__xludf.DUMMYFUNCTION("""COMPUTED_VALUE"""),"Aegis of the Seraph Recipe") -> Aegis of the Seraph Recipe | AK6: =IFERROR(__xludf.DUMMYFUNCTION("""COMPUTED_VALUE"""),353.5728) -> 353.5728 | AL6: =IFERROR(__xludf.DUMMYFUNCTION("""COMPUTED_VALUE"""),"Stormguard Shield Recipe") -> Stormguard Shield Recipe | AM6: =IFERROR(__xludf.DUMMYFUNCTION("""COMPUTED_VALUE"""),361.76) -> 361.76 | AN6: =IFERROR(__xludf.DUMMYFUNCTION("""COMPUTED_VALUE"""),"Riverbend Infusion Recipe") -> Riverbend Infusion Recipe | AO6: =IFERROR(__xludf.DUMMYFUNCTION("""COMPUTED_VALUE"""),203.301504) -> 203.3015 | AP6: =IFERROR(__xludf.DUMMYFUNCTION("""COMPUTED_VALUE"""),"Tampering Essence Recipe") -> Tampering Essence Recipe | AQ6: =IFERROR(__xludf.DUMMYFUNCTION("""COMPUTED_VALUE"""),262.752) -> 262.752 | AR6: =IFERROR(__xludf.DUMMYFUNCTION("""COMPUTED_VALUE"""),"Riverbend Infusion Recipe (Untradable)") -> Riverbend Infusion Recipe (Untradable) | AS6: =IFERROR(__xludf.DUMMYFUNCTION("""COMPUTED_VALUE"""),0.0) -> 0 | AT6: =IFERROR(__xludf.DUMMYFUNCTION("""COMPUTED_VALUE"""),"Tampering Essence Recipe (Untradable)") -> Tampering Essence Recipe (Untradable) | AU6: =IFERROR(__xludf.DUMMYFUNCTION("""COMPUTED_VALUE"""),0.0) -> 0
A7: Cursed Asylum | B7: =B6+G6 -> 58 | C7: 6000 | D7: =2*3600+16*60+40 -> 8200 | E7: =SUM(H7:ABF7)-C7 -> 7563.9225 | F7: =E7/(D7/3600) -> 3320.7464 | G7: 24 | H7: =IFERROR(__xludf.DUMMYFUNCTION("MAP(OFFSET($H$1,0,0,1,G7*2),LAMBDA(c,IF(ISEVEN(COLUMN(c)),INDIRECT(ADDRESS(REGEXEXTRACT(c,""\d+"")+$B7,14,1,TRUE,""Market"")),INDIRECT(ADDRESS(REGEXEXTRACT(c,""\d+"")+$B7,15,3,,""Market""))*(INDIRECT(ADDRESS(REGEXEXTRACT(c,""\d+"")+$B7,17,3,,""Market""))*"&"(1+$B$27/100)))))"),"Frostbite Recipe") -> Frostbite Recipe | I7: =IFERROR(__xludf.DUMMYFUNCTION("""COMPUTED_VALUE"""),20.808) -> 20.808 | J7: =IFERROR(__xludf.DUMMYFUNCTION("""COMPUTED_VALUE"""),"Stormbringer Recipe") -> Stormbringer Recipe | K7: =IFERROR(__xludf.DUMMYFUNCTION("""COMPUTED_VALUE"""),23.827199999999998) -> 23.8272 | L7: =IFERROR(__xludf.DUMMYFUNCTION("""COMPUTED_VALUE"""),"Bloodletter Recipe") -> Bloodletter Recipe | M7: =IFERROR(__xludf.DUMMYFUNCTION("""COMPUTED_VALUE"""),15.912) -> 15.912 | N7: =IFERROR(__xludf.DUMMYFUNCTION("""COMPUTED_VALUE"""),"Whisperblade Recipe") -> Whisperblade Recipe | O7: =IFERROR(__xludf.DUMMYFUNCTION("""COMPUTED_VALUE"""),10.879999999999999) -> 10.88 | P7: =IFERROR(__xludf.DUMMYFUNCTION("""COMPUTED_VALUE"""),"Shadow Shot Recipe") -> Shadow Shot Recipe | Q7: =IFERROR(__xludf.DUMMYFUNCTION("""COMPUTED_VALUE"""),19.559520000000003) -> 19.55952 | R7: =IFERROR(__xludf.DUMMYFUNCTION("""COMPUTED_VALUE"""),"Frostbite Shot Recipe") -> Frostbite Shot Recipe | S7: =IFERROR(__xludf.DUMMYFUNCTION("""COMPUTED_VALUE"""),21.759999999999998) -> 21.76 | T7: =IFERROR(__xludf.DUMMYFUNCTION("""COMPUTED_VALUE"""),"Frostguard Visage Recipe") -> Frostguard Visage Recipe | U7: =IFERROR(__xludf.DUMMYFUNCTION("""COMPUTED_VALUE"""),16.8912) -> 16.8912 | V7: =IFERROR(__xludf.DUMMYFUNCTION("""COMPUTED_VALUE"""),"Sentinel's Gaze Recipe") -> Sentinel's Gaze Recipe | W7: =IFERROR(__xludf.DUMMYFUNCTION("""COMPUTED_VALUE"""),21.759999999999998) -> 21.76 | X7: =IFERROR(__xludf.DUMMYFUNCTION("""COMPUTED_VALUE"""),"Dragonfire Grasp Recipe") -> Dragonfire Grasp Recipe | Y7: =IFERROR(__xludf.DUMMYFUNCTION("""COMPUTED_VALUE"""),48.96) -> 48.96 | Z7: =IFERROR(__xludf.DUMMYFUNCTION("""COMPUTED_VALUE"""),"Shadowstrike Grips Recipe") -> Shadowstrike Grips Recipe | AA7: =IFERROR(__xludf.DUMMYFUNCTION("""COMPUTED_VALUE"""),24.455520000000003) -> 24.45552 | AB7: =IFERROR(__xludf.DUMMYFUNCTION("""COMPUTED_VALUE"""),"Frostbite Gauntlets Recipe") -> Frostbite Gauntlets Recipe | AC7: =IFERROR(__xludf.DUMMYFUNCTION("""COMPUTED_VALUE"""),54.37824) -> 54.37824 | AD7: =IFERROR(__xludf.DUMMYFUNCTION("""COMPUTED_VALUE"""),"Shadowcloak Vestments Recipe") -> Shadowcloak Vestments Recipe | AE7: =IFERROR(__xludf.DUMMYFUNCTION("""COMPUTED_VALUE"""),46.512) -> 46.512 | AF7: =IFERROR(__xludf.DUMMYFUNCTION("""COMPUTED_VALUE"""),"Frostbite Plate Recipe") -> Frostbite Plate Recipe | AG7: =IFERROR(__xludf.DUMMYFUNCTION("""COMPUTED_VALUE"""),31.007999999999996) -> 31.008 | AH7: =IFERROR(__xludf.DUMMYFUNCTION("""COMPUTED_VALUE"""),"Frostbite Legguards Recipe") -> Frostbite Legguards Recipe | AI7: =IFERROR(__xludf.DUMMYFUNCTION("""COMPUTED_VALUE"""),22.032) -> 22.032 | AJ7: =IFERROR(__xludf.DUMMYFUNCTION("""COMPUTED_VALUE"""),"Sentinel's Resolve Recipe") -> Sentinel's Resolve Recipe | AK7: =IFERROR(__xludf.DUMMYFUNCTION("""COMPUTED_VALUE"""),20.671999999999997) -> 20.672 | AL7: =IFERROR(__xludf.DUMMYFUNCTION("""COMPUTED_VALUE"""),"Shadowstep Footwear Recipe") -> Shadowstep Footwear Recipe | AM7: =IFERROR(__xludf.DUMMYFUNCTION("""COMPUTED_VALUE"""),97.89552) -> 97.89552 | AN7: =IFERROR(__xludf.DUMMYFUNCTION("""COMPUTED_VALUE"""),"Soulward Barrier Recipe") -> Soulward Barrier Recipe | AO7: =IFERROR(__xludf.DUMMYFUNCTION("""COMPUTED_VALUE"""),318.24) -> 318.24 | AP7: =IFERROR(__xludf.DUMMYFUNCTION("""COMPUTED_VALUE"""),"Hydra's Coil Recipe") -> Hydra's Coil Recipe | AQ7: =IFERROR(__xludf.DUMMYFUNCTION("""COMPUTED_VALUE"""),4243.2) -> 4243.2 | AR7: =IFERROR(__xludf.DUMMYFUNCTION("""COMPUTED_VALUE"""),"Earthshaker Recipe") -> Earthshaker Recipe | AS7: =IFERROR(__xludf.DUMMYFUNCTION("""COMPUTED_VALUE"""),6092.799999999999) -> 6092.8 | AT7: =IFERROR(__xludf.DUMMYFUNCTION("""COMPUTED_VALUE"""),"Grove Cleaver Recipe") -> Grove Cleaver Recipe | AU7: =IFERROR(__xludf.DUMMYFUNCTION("""COMPUTED_VALUE"""),2312.0) -> 2312 | AV7: =IFERROR(__xludf.DUMMYFUNCTION("""COMPUTED_VALUE"""),"Shieldbearer's Infusion Recipe") -> Shieldbearer's Infusion Recipe | AW7: =IFERROR(__xludf.DUMMYFUNCTION("""COMPUTED_VALUE"""),66.099264) -> 66.099264 | AX7: =IFERROR(__xludf.DUMMYFUNCTION("""COMPUTED_VALUE"""),"Unyielding Fortitude Recipe") -> Unyielding Fortitude Recipe | AY7: =IFERROR(__xludf.DUMMYFUNCTION("""COMPUTED_VALUE"""),34.272) -> 34.272 | AZ7: =IFERROR(__xludf.DUMMYFUNCTION("""COMPUTED_VALUE"""),"Shieldbearer's Infusion Recipe (Untradable)") -> Shieldbearer's Infusion Recipe (Untradable) | BA7: =IFERROR(__xludf.DUMMYFUNCTION("""COMPUTED_VALUE"""),0.0) -> 0 | BB7: =IFERROR(__xludf.DUMMYFUNCTION("""COMPUTED_VALUE"""),"Unyielding Fortitude Recipe (Untradable)") -> Unyielding Fortitude Recipe (Untradable) | BC7: =IFERROR(__xludf.DUMMYFUNCTION("""COMPUTED_VALUE"""),0.0) -> 0
A8: Forgotten Archives | B8: =B7+G7 -> 82 | C8: 9000 | D8: =2*3600+20*60 -> 8400 | E8: =SUM(H8:ABF8)-C8 -> -6816.8097 | F8: =E8/(D8/3600) -> -2921.4899 | G8: 20 | H8: =IFERROR(__xludf.DUMMYFUNCTION("MAP(OFFSET($H$1,0,0,1,G8*2),LAMBDA(c,IF(ISEVEN(COLUMN(c)),INDIRECT(ADDRESS(REGEXEXTRACT(c,""\d+"")+$B8,14,1,TRUE,""Market"")),INDIRECT(ADDRESS(REGEXEXTRACT(c,""\d+"")+$B8,15,3,,""Market""))*(INDIRECT(ADDRESS(REGEXEXTRACT(c,""\d+"")+$B8,17,3,,""Market""))*"&"(1+$B$27/100)))))"),"Doomblade Recipe") -> Doomblade Recipe | I8: =IFERROR(__xludf.DUMMYFUNCTION("""COMPUTED_VALUE"""),173.39999999999998) -> 173.4 | J8: =IFERROR(__xludf.DUMMYFUNCTION("""COMPUTED_VALUE"""),"Serpentstrike Recipe") -> Serpentstrike Recipe | K8: =IFERROR(__xludf.DUMMYFUNCTION("""COMPUTED_VALUE"""),22.6304) -> 22.6304 | L8: =IFERROR(__xludf.DUMMYFUNCTION("""COMPUTED_VALUE"""),"Serpent's Kiss Recipe") -> Serpent's Kiss Recipe | M8: =IFERROR(__xludf.DUMMYFUNCTION("""COMPUTED_VALUE"""),18.258) -> 18.258 | N8: =IFERROR(__xludf.DUMMYFUNCTION("""COMPUTED_VALUE"""),"Moonshadow Recipe") -> Moonshadow Recipe | O8: =IFERROR(__xludf.DUMMYFUNCTION("""COMPUTED_VALUE"""),21.216) -> 21.216 | P8: =IFERROR(__xludf.DUMMYFUNCTION("""COMPUTED_VALUE"""),"Serpent's Arrow Recipe") -> Serpent's Arrow Recipe | Q8: =IFERROR(__xludf.DUMMYFUNCTION("""COMPUTED_VALUE"""),16.218) -> 16.218 | R8: =IFERROR(__xludf.DUMMYFUNCTION("""COMPUTED_VALUE"""),"Viper Recipe") -> Viper Recipe | S8: =IFERROR(__xludf.DUMMYFUNCTION("""COMPUTED_VALUE"""),22.984) -> 22.984 | T8: =IFERROR(__xludf.DUMMYFUNCTION("""COMPUTED_VALUE"""),"Celestial Crown Recipe") -> Celestial Crown Recipe | U8: =IFERROR(__xludf.DUMMYFUNCTION("""COMPUTED_VALUE"""),70.38) -> 70.38 | V8: =IFERROR(__xludf.DUMMYFUNCTION("""COMPUTED_VALUE"""),"Emberfire Helm Recipe") -> Emberfire Helm Recipe | W8: =IFERROR(__xludf.DUMMYFUNCTION("""COMPUTED_VALUE"""),49.504000000000005) -> 49.504 | X8: =IFERROR(__xludf.DUMMYFUNCTION("""COMPUTED_VALUE"""),"Titan's Embrace Recipe") -> Titan's Embrace Recipe | Y8: =IFERROR(__xludf.DUMMYFUNCTION("""COMPUTED_VALUE"""),61.199999999999996) -> 61.2 | Z8: =IFERROR(__xludf.DUMMYFUNCTION("""COMPUTED_VALUE"""),"Celestial Touch Gloves Recipe") -> Celestial Touch Gloves Recipe | AA8: =IFERROR(__xludf.DUMMYFUNCTION("""COMPUTED_VALUE"""),67.16632) -> 67.16632 | AB8: =IFERROR(__xludf.DUMMYFUNCTION("""COMPUTED_VALUE"""),"Sentinel's Embrace Recipe") -> Sentinel's Embrace Recipe | AC8: =IFERROR(__xludf.DUMMYFUNCTION("""COMPUTED_VALUE"""),20.3388) -> 20.3388 | AD8: =IFERROR(__xludf.DUMMYFUNCTION("""COMPUTED_VALUE"""),"Celestial Striders Recipe") -> Celestial Striders Recipe | AE8: =IFERROR(__xludf.DUMMYFUNCTION("""COMPUTED_VALUE"""),163.2) -> 163.2 | AF8: =IFERROR(__xludf.DUMMYFUNCTION("""COMPUTED_VALUE"""),"Frostbite Walkers Recipe") -> Frostbite Walkers Recipe | AG8: =IFERROR(__xludf.DUMMYFUNCTION("""COMPUTED_VALUE"""),61.17959999999999) -> 61.1796 | AH8: =IFERROR(__xludf.DUMMYFUNCTION("""COMPUTED_VALUE"""),"Guardian's Stride Recipe") -> Guardian's Stride Recipe | AI8: =IFERROR(__xludf.DUMMYFUNCTION("""COMPUTED_VALUE"""),46.6752) -> 46.6752 | AJ8: =IFERROR(__xludf.DUMMYFUNCTION("""COMPUTED_VALUE"""),"Flamebreaker Buckler Recipe") -> Flamebreaker Buckler Recipe | AK8: =IFERROR(__xludf.DUMMYFUNCTION("""COMPUTED_VALUE"""),458.99999999999994) -> 459 | AL8: =IFERROR(__xludf.DUMMYFUNCTION("""COMPUTED_VALUE"""),"Shadowbound Ward Recipe") -> Shadowbound Ward Recipe | AM8: =IFERROR(__xludf.DUMMYFUNCTION("""COMPUTED_VALUE"""),322.32) -> 322.32 | AN8: =IFERROR(__xludf.DUMMYFUNCTION("""COMPUTED_VALUE"""),"Stoneheart Solution Recipe") -> Stoneheart Solution Recipe | AO8: =IFERROR(__xludf.DUMMYFUNCTION("""COMPUTED_VALUE"""),97.91999999999999) -> 97.92 | AP8: =IFERROR(__xludf.DUMMYFUNCTION("""COMPUTED_VALUE"""),"Lightning Sprint Recipe") -> Lightning Sprint Recipe | AQ8: =IFERROR(__xludf.DUMMYFUNCTION("""COMPUTED_VALUE"""),489.5999999999999) -> 489.6 | AR8: =IFERROR(__xludf.DUMMYFUNCTION("""COMPUTED_VALUE"""),"Stoneheart Solution Recipe (Untradable)") -> Stoneheart Solution Recipe (Untradable) | AS8: =IFERROR(__xludf.DUMMYFUNCTION("""COMPUTED_VALUE"""),0.0) -> 0 | AT8: =IFERROR(__xludf.DUMMYFUNCTION("""COMPUTED_VALUE"""),"Lightning Sprint Recipe (Untradable)") -> Lightning Sprint Recipe (Untradable) | AU8: =IFERROR(__xludf.DUMMYFUNCTION("""COMPUTED_VALUE"""),0.0) -> 0
A9: Crystal Forge | B9: =B8+G8 -> 102 | C9: 12000 | D9: =2*3600+23*60+20 -> 8600 | E9: =SUM(H9:ABF9)-C9 -> 10139.104 | F9: =E9/(D9/3600) -> 4244.2761 | G9: 23 | H9: =IFERROR(__xludf.DUMMYFUNCTION("MAP(OFFSET($H$1,0,0,1,G9*2),LAMBDA(c,IF(ISEVEN(COLUMN(c)),INDIRECT(ADDRESS(REGEXEXTRACT(c,""\d+"")+$B9,14,1,TRUE,""Market"")),INDIRECT(ADDRESS(REGEXEXTRACT(c,""\d+"")+$B9,15,3,,""Market""))*(INDIRECT(ADDRESS(REGEXEXTRACT(c,""\d+"")+$B9,17,3,,""Market""))*"&"(1+$B$27/100)))))"),"Celestial Edge Recipe") -> Celestial Edge Recipe | I9: =IFERROR(__xludf.DUMMYFUNCTION("""COMPUTED_VALUE"""),40.8) -> 40.8 | J9: =IFERROR(__xludf.DUMMYFUNCTION("""COMPUTED_VALUE"""),"Bloodmoon Sword Recipe") -> Bloodmoon Sword Recipe | K9: =IFERROR(__xludf.DUMMYFUNCTION("""COMPUTED_VALUE"""),29.8452) -> 29.8452 | L9: =IFERROR(__xludf.DUMMYFUNCTION("""COMPUTED_VALUE"""),"Quickstrike Recipe") -> Quickstrike Recipe | M9: =IFERROR(__xludf.DUMMYFUNCTION("""COMPUTED_VALUE"""),12.716) -> 12.716 | N9: =IFERROR(__xludf.DUMMYFUNCTION("""COMPUTED_VALUE"""),"Runeblade Dagger Recipe") -> Runeblade Dagger Recipe | O9: =IFERROR(__xludf.DUMMYFUNCTION("""COMPUTED_VALUE"""),11.968) -> 11.968 | P9: =IFERROR(__xludf.DUMMYFUNCTION("""COMPUTED_VALUE"""),"Moonshot Recipe") -> Moonshot Recipe | Q9: =IFERROR(__xludf.DUMMYFUNCTION("""COMPUTED_VALUE"""),9.724) -> 9.724 | R9: =IFERROR(__xludf.DUMMYFUNCTION("""COMPUTED_VALUE"""),"Stormsong Recipe") -> Stormsong Recipe | S9: =IFERROR(__xludf.DUMMYFUNCTION("""COMPUTED_VALUE"""),11.8932) -> 11.8932 | T9: =IFERROR(__xludf.DUMMYFUNCTION("""COMPUTED_VALUE"""),"Thunder Helm Recipe") -> Thunder Helm Recipe | U9: =IFERROR(__xludf.DUMMYFUNCTION("""COMPUTED_VALUE"""),13.44904) -> 13.44904 | V9: =IFERROR(__xludf.DUMMYFUNCTION("""COMPUTED_VALUE"""),"Emberfist Recipe") -> Emberfist Recipe | W9: =IFERROR(__xludf.DUMMYFUNCTION("""COMPUTED_VALUE"""),14.930079999999998) -> 14.93008 | X9: =IFERROR(__xludf.DUMMYFUNCTION("""COMPUTED_VALUE"""),"Celestial Radiance Recipe") -> Celestial Radiance Recipe | Y9: =IFERROR(__xludf.DUMMYFUNCTION("""COMPUTED_VALUE"""),57.03839999999999) -> 57.0384 | Z9: =IFERROR(__xludf.DUMMYFUNCTION("""COMPUTED_VALUE"""),"Ironbark Cuirass Recipe") -> Ironbark Cuirass Recipe | AA9: =IFERROR(__xludf.DUMMYFUNCTION("""COMPUTED_VALUE"""),29.15704) -> 29.15704 | AB9: =IFERROR(__xludf.DUMMYFUNCTION("""COMPUTED_VALUE"""),"Emberfoot Greaves Recipe") -> Emberfoot Greaves Recipe | AC9: =IFERROR(__xludf.DUMMYFUNCTION("""COMPUTED_VALUE"""),16.303679999999996) -> 16.30368 | AD9: =IFERROR(__xludf.DUMMYFUNCTION("""COMPUTED_VALUE"""),"Thunderclash Greaves Recipe") -> Thunderclash Greaves Recipe | AE9: =IFERROR(__xludf.DUMMYFUNCTION("""COMPUTED_VALUE"""),112.18504) -> 112.18504 | AF9: =IFERROR(__xludf.DUMMYFUNCTION("""COMPUTED_VALUE"""),"Celestial Ascenders Recipe") -> Celestial Ascenders Recipe | AG9: =IFERROR(__xludf.DUMMYFUNCTION("""COMPUTED_VALUE"""),30.991679999999995) -> 30.99168 | AH9: =IFERROR(__xludf.DUMMYFUNCTION("""COMPUTED_VALUE"""),"Emberfoot Boots Recipe") -> Emberfoot Boots Recipe | AI9: =IFERROR(__xludf.DUMMYFUNCTION("""COMPUTED_VALUE"""),44.879999999999995) -> 44.88 | AJ9: =IFERROR(__xludf.DUMMYFUNCTION("""COMPUTED_VALUE"""),"Frostbite Guard Recipe") -> Frostbite Guard Recipe | AK9: =IFERROR(__xludf.DUMMYFUNCTION("""COMPUTED_VALUE"""),163.2) -> 163.2 | AL9: =IFERROR(__xludf.DUMMYFUNCTION("""COMPUTED_VALUE"""),"Sentinel's Bulwark Recipe") -> Sentinel's Bulwark Recipe | AM9: =IFERROR(__xludf.DUMMYFUNCTION("""COMPUTED_VALUE"""),187.0) -> 187 | AN9: =IFERROR(__xludf.DUMMYFUNCTION("""COMPUTED_VALUE"""),"Ocean's Whisper Recipe") -> Ocean's Whisper Recipe | AO9: =IFERROR(__xludf.DUMMYFUNCTION("""COMPUTED_VALUE"""),9465.599999999999) -> 9465.6 | AP9: =IFERROR(__xludf.DUMMYFUNCTION("""COMPUTED_VALUE"""),"Stone Splinter Recipe") -> Stone Splinter Recipe | AQ9: =IFERROR(__xludf.DUMMYFUNCTION("""COMPUTED_VALUE"""),8241.58368) -> 8241.5837 | AR9: =IFERROR(__xludf.DUMMYFUNCTION("""COMPUTED_VALUE"""),"Branchbane Hatchet Recipe") -> Branchbane Hatchet Recipe | AS9: =IFERROR(__xludf.DUMMYFUNCTION("""COMPUTED_VALUE"""),3590.3999999999996) -> 3590.4 | AT9: =IFERROR(__xludf.DUMMYFUNCTION("""COMPUTED_VALUE"""),"Twinstrike Elixir Recipe") -> Twinstrike Elixir Recipe | AU9: =IFERROR(__xludf.DUMMYFUNCTION("""COMPUTED_VALUE"""),22.847999999999995) -> 22.848 | AV9: =IFERROR(__xludf.DUMMYFUNCTION("""COMPUTED_VALUE"""),"Frenzy Potion Recipe") -> Frenzy Potion Recipe | AW9: =IFERROR(__xludf.DUMMYFUNCTION("""COMPUTED_VALUE"""),32.59103999999999) -> 32.59104 | AX9: =IFERROR(__xludf.DUMMYFUNCTION("""COMPUTED_VALUE"""),"Twinstrike Elixir Recipe (Untradable)") -> Twinstrike Elixir Recipe (Untradable) | AY9: =IFERROR(__xludf.DUMMYFUNCTION("""COMPUTED_VALUE"""),0.0) -> 0 | AZ9: =IFERROR(__xludf.DUMMYFUNCTION("""COMPUTED_VALUE"""),"Frenzy Potion Recipe (Untradable)") -> Frenzy Potion Recipe (Untradable) | BA9: =IFERROR(__xludf.DUMMYFUNCTION("""COMPUTED_VALUE"""),0.0) -> 0
A10: Frostbite Spire | B10: =B9+G9 -> 125 | C10: 16000 | D10: =2*3600+26*60+40 -> 8800 | E10: =SUM(H10:ABF10)-C10 -> -9514.7414 | F10: =E10/(D10/3600) -> -3892.3942 | G10: 20 | H10: =IFERROR(__xludf.DUMMYFUNCTION("MAP(OFFSET($H$1,0,0,1,G10*2),LAMBDA(c,IF(ISEVEN(COLUMN(c)),INDIRECT(ADDRESS(REGEXEXTRACT(c,""\d+"")+$B10,14,1,TRUE,""Market"")),INDIRECT(ADDRESS(REGEXEXTRACT(c,""\d+"")+$B10,15,3,,""Market""))*(INDIRECT(ADDRESS(REGEXEXTRACT(c,""\d+"")+$B10,17,3,,""Market"&"""))*(1+$B$27/100)))))"),"Whisperwind Sword Recipe") -> Whisperwind Sword Recipe | I10: =IFERROR(__xludf.DUMMYFUNCTION("""COMPUTED_VALUE"""),44.349599999999995) -> 44.3496 | J10: =IFERROR(__xludf.DUMMYFUNCTION("""COMPUTED_VALUE"""),"Voidslayer Recipe") -> Voidslayer Recipe | K10: =IFERROR(__xludf.DUMMYFUNCTION("""COMPUTED_VALUE"""),74.25599999999999) -> 74.256 | L10: =IFERROR(__xludf.DUMMYFUNCTION("""COMPUTED_VALUE"""),"Shadowfang Recipe") -> Shadowfang Recipe | M10: =IFERROR(__xludf.DUMMYFUNCTION("""COMPUTED_VALUE"""),182.47799999999998) -> 182.478 | N10: =IFERROR(__xludf.DUMMYFUNCTION("""COMPUTED_VALUE"""),"Emberheart Recipe") -> Emberheart Recipe | O10: =IFERROR(__xludf.DUMMYFUNCTION("""COMPUTED_VALUE"""),20.379599999999996) -> 20.3796 | P10: =IFERROR(__xludf.DUMMYFUNCTION("""COMPUTED_VALUE"""),"Otto's Mask Recipe") -> Otto's Mask Recipe | Q10: =IFERROR(__xludf.DUMMYFUNCTION("""COMPUTED_VALUE"""),67.9864) -> 67.9864 | R10: =IFERROR(__xludf.DUMMYFUNCTION("""COMPUTED_VALUE"""),"Shadowbane Visor Recipe") -> Shadowbane Visor Recipe | S10: =IFERROR(__xludf.DUMMYFUNCTION("""COMPUTED_VALUE"""),147.89999999999998) -> 147.9 | T10: =IFERROR(__xludf.DUMMYFUNCTION("""COMPUTED_VALUE"""),"Thunderclap Recipe") -> Thunderclap Recipe | U10: =IFERROR(__xludf.DUMMYFUNCTION("""COMPUTED_VALUE"""),65.26639999999999) -> 65.2664 | V10: =IFERROR(__xludf.DUMMYFUNCTION("""COMPUTED_VALUE"""),"Soulgrasp Recipe") -> Soulgrasp Recipe | W10: =IFERROR(__xludf.DUMMYFUNCTION("""COMPUTED_VALUE"""),29.58) -> 29.58 | X10: =IFERROR(__xludf.DUMMYFUNCTION("""COMPUTED_VALUE"""),"Flameguard Plate Recipe") -> Flameguard Plate Recipe | Y10: =IFERROR(__xludf.DUMMYFUNCTION("""COMPUTED_VALUE"""),176.7728) -> 176.7728 | Z10: =IFERROR(__xludf.DUMMYFUNCTION("""COMPUTED_VALUE"""),"Stormbreaker Mail Recipe") -> Stormbreaker Mail Recipe | AA10: =IFERROR(__xludf.DUMMYFUNCTION("""COMPUTED_VALUE"""),71.39999999999999) -> 71.4 | AB10: =IFERROR(__xludf.DUMMYFUNCTION("""COMPUTED_VALUE"""),"Soulforge Legplates Recipe") -> Soulforge Legplates Recipe | AC10: =IFERROR(__xludf.DUMMYFUNCTION("""COMPUTED_VALUE"""),27.2) -> 27.2 | AD10: =IFERROR(__xludf.DUMMYFUNCTION("""COMPUTED_VALUE"""),"Shadowbane Greaves Recipe") -> Shadowbane Greaves Recipe | AE10: =IFERROR(__xludf.DUMMYFUNCTION("""COMPUTED_VALUE"""),40.8) -> 40.8 | AF10: =IFERROR(__xludf.DUMMYFUNCTION("""COMPUTED_VALUE"""),"Thunderstrike Steps Recipe") -> Thunderstrike Steps Recipe | AG10: =IFERROR(__xludf.DUMMYFUNCTION("""COMPUTED_VALUE"""),61.199999999999996) -> 61.2 | AH10: =IFERROR(__xludf.DUMMYFUNCTION("""COMPUTED_VALUE"""),"Soulwalkers Recipe") -> Soulwalkers Recipe | AI10: =IFERROR(__xludf.DUMMYFUNCTION("""COMPUTED_VALUE"""),39.7698) -> 39.7698 | AJ10: =IFERROR(__xludf.DUMMYFUNCTION("""COMPUTED_VALUE"""),"Celestial Aegis Recipe") -> Celestial Aegis Recipe | AK10: =IFERROR(__xludf.DUMMYFUNCTION("""COMPUTED_VALUE"""),231.2) -> 231.2 | AL10: =IFERROR(__xludf.DUMMYFUNCTION("""COMPUTED_VALUE"""),"Thunderstrike Barrier Recipe") -> Thunderstrike Barrier Recipe | AM10: =IFERROR(__xludf.DUMMYFUNCTION("""COMPUTED_VALUE"""),161.83999999999997) -> 161.84 | AN10: =IFERROR(__xludf.DUMMYFUNCTION("""COMPUTED_VALUE"""),"Dragonblood Tonic Recipe") -> Dragonblood Tonic Recipe | AO10: =IFERROR(__xludf.DUMMYFUNCTION("""COMPUTED_VALUE"""),1672.7999999999997) -> 1672.8 | AP10: =IFERROR(__xludf.DUMMYFUNCTION("""COMPUTED_VALUE"""),"Gourmet Essence Recipe ") -> Gourmet Essence Recipe | AQ10: =IFERROR(__xludf.DUMMYFUNCTION("""COMPUTED_VALUE"""),3370.0799999999995) -> 3370.08 | AR10: =IFERROR(__xludf.DUMMYFUNCTION("""COMPUTED_VALUE"""),"Dragonblood Tonic Recipe (Untradable)") -> Dragonblood Tonic Recipe (Untradable) | AS10: =IFERROR(__xludf.DUMMYFUNCTION("""COMPUTED_VALUE"""),0.0) -> 0 | AT10: =IFERROR(__xludf.DUMMYFUNCTION("""COMPUTED_VALUE"""),"Gourmet Essence Recipe (Untradable)") -> Gourmet Essence Recipe (Untradable) | AU10: =IFERROR(__xludf.DUMMYFUNCTION("""COMPUTED_VALUE"""),0.0) -> 0
A11: Zenith's Sanctum | B11: =B10+G10 -> 145 | C11: 20000 | D11: =2*3600+30*60+0 -> 9000 | E11: =SUM(H11:ABF11)-C11 -> -9816.675 | F11: =E11/(D11/3600) -> -3926.67 | G11: 20 | H11: =IFERROR(__xludf.DUMMYFUNCTION("MAP(OFFSET($H$1,0,0,1,G11*2),LAMBDA(c,IF(ISEVEN(COLUMN(c)),INDIRECT(ADDRESS(REGEXEXTRACT(c,""\d+"")+$B11,14,1,TRUE,""Market"")),INDIRECT(ADDRESS(REGEXEXTRACT(c,""\d+"")+$B11,15,3,,""Market""))*(INDIRECT(ADDRESS(REGEXEXTRACT(c,""\d+"")+$B11,17,3,,""Market"&"""))*(1+$B$27/100)))))"),"Sunfire Recipe") -> Sunfire Recipe | I11: =IFERROR(__xludf.DUMMYFUNCTION("""COMPUTED_VALUE"""),104.44799999999998) -> 104.448 | J11: =IFERROR(__xludf.DUMMYFUNCTION("""COMPUTED_VALUE"""),"Flamebrand Recipe") -> Flamebrand Recipe | K11: =IFERROR(__xludf.DUMMYFUNCTION("""COMPUTED_VALUE"""),47.59047999999999) -> 47.59048 | L11: =IFERROR(__xludf.DUMMYFUNCTION("""COMPUTED_VALUE"""),"Soulshard Recipe") -> Soulshard Recipe | M11: =IFERROR(__xludf.DUMMYFUNCTION("""COMPUTED_VALUE"""),159.11999999999998) -> 159.12 | N11: =IFERROR(__xludf.DUMMYFUNCTION("""COMPUTED_VALUE"""),"Piercer Recipe") -> Piercer Recipe | O11: =IFERROR(__xludf.DUMMYFUNCTION("""COMPUTED_VALUE"""),22.848) -> 22.848 | P11: =IFERROR(__xludf.DUMMYFUNCTION("""COMPUTED_VALUE"""),"Sunseeker Recipe") -> Sunseeker Recipe | Q11: =IFERROR(__xludf.DUMMYFUNCTION("""COMPUTED_VALUE"""),122.39999999999998) -> 122.4 | R11: =IFERROR(__xludf.DUMMYFUNCTION("""COMPUTED_VALUE"""),"Windborne Casque Recipe") -> Windborne Casque Recipe | S11: =IFERROR(__xludf.DUMMYFUNCTION("""COMPUTED_VALUE"""),38.08) -> 38.08 | T11: =IFERROR(__xludf.DUMMYFUNCTION("""COMPUTED_VALUE"""),"Stormbreaker Helm Recipe") -> Stormbreaker Helm Recipe | U11: =IFERROR(__xludf.DUMMYFUNCTION("""COMPUTED_VALUE"""),150.95183999999998) -> 150.95184 | V11: =IFERROR(__xludf.DUMMYFUNCTION("""COMPUTED_VALUE"""),"Shadowstep Gauntlets Recipe") -> Shadowstep Gauntlets Recipe | W11: =IFERROR(__xludf.DUMMYFUNCTION("""COMPUTED_VALUE"""),47.59047999999999) -> 47.59048 | X11: =IFERROR(__xludf.DUMMYFUNCTION("""COMPUTED_VALUE"""),"Sentinel's Gauntlets Recipe") -> Sentinel's Gauntlets Recipe | Y11: =IFERROR(__xludf.DUMMYFUNCTION("""COMPUTED_VALUE"""),69.35999999999999) -> 69.36 | Z11: =IFERROR(__xludf.DUMMYFUNCTION("""COMPUTED_VALUE"""),"Shadeweave Raiment Recipe") -> Shadeweave Raiment Recipe | AA11: =IFERROR(__xludf.DUMMYFUNCTION("""COMPUTED_VALUE"""),185.64) -> 185.64 | AB11: =IFERROR(__xludf.DUMMYFUNCTION("""COMPUTED_VALUE"""),"Crystalheart Plate Recipe") -> Crystalheart Plate Recipe | AC11: =IFERROR(__xludf.DUMMYFUNCTION("""COMPUTED_VALUE"""),195.83999999999997) -> 195.84 | AD11: =IFERROR(__xludf.DUMMYFUNCTION("""COMPUTED_VALUE"""),"Windrider Greaves Recipe") -> Windrider Greaves Recipe | AE11: =IFERROR(__xludf.DUMMYFUNCTION("""COMPUTED_VALUE"""),142.79999999999998) -> 142.8 | AF11: =IFERROR(__xludf.DUMMYFUNCTION("""COMPUTED_VALUE"""),"Stormbreaker Treads Recipe") -> Stormbreaker Treads Recipe | AG11: =IFERROR(__xludf.DUMMYFUNCTION("""COMPUTED_VALUE"""),158.712) -> 158.712 | AH11: =IFERROR(__xludf.DUMMYFUNCTION("""COMPUTED_VALUE"""),"Shadowbane Footguards Recipe") -> Shadowbane Footguards Recipe | AI11: =IFERROR(__xludf.DUMMYFUNCTION("""COMPUTED_VALUE"""),142.79047999999997) -> 142.79048 | AJ11: =IFERROR(__xludf.DUMMYFUNCTION("""COMPUTED_VALUE"""),"Windrider Striders Recipe") -> Windrider Striders Recipe | AK11: =IFERROR(__xludf.DUMMYFUNCTION("""COMPUTED_VALUE"""),122.39183999999999) -> 122.39184 | AL11: =IFERROR(__xludf.DUMMYFUNCTION("""COMPUTED_VALUE"""),"Essenceweave Shield Recipe") -> Essenceweave Shield Recipe | AM11: =IFERROR(__xludf.DUMMYFUNCTION("""COMPUTED_VALUE"""),104.68191999999999) -> 104.68192 | AN11: =IFERROR(__xludf.DUMMYFUNCTION("""COMPUTED_VALUE"""),"Wraithbane Essence Recipe") -> Wraithbane Essence Recipe | AO11: =IFERROR(__xludf.DUMMYFUNCTION("""COMPUTED_VALUE"""),5712.0) -> 5712 | AP11: =IFERROR(__xludf.DUMMYFUNCTION("""COMPUTED_VALUE"""),"Thunderfury Brew Recipe") -> Thunderfury Brew Recipe | AQ11: =IFERROR(__xludf.DUMMYFUNCTION("""COMPUTED_VALUE"""),2656.08) -> 2656.08 | AR11: =IFERROR(__xludf.DUMMYFUNCTION("""COMPUTED_VALUE"""),"Wraithbane Essence Recipe (Untradable)") -> Wraithbane Essence Recipe (Untradable) | AS11: =IFERROR(__xludf.DUMMYFUNCTION("""COMPUTED_VALUE"""),0.0) -> 0 | AT11: =IFERROR(__xludf.DUMMYFUNCTION("""COMPUTED_VALUE"""),"Thunderfury Brew Recipe (Untradable)") -> Thunderfury Brew Recipe (Untradable) | AU11: =IFERROR(__xludf.DUMMYFUNCTION("""COMPUTED_VALUE"""),0.0) -> 0
A12: Mirage Citadel | B12: =B11+G11 -> 165 | C12: 26000 | D12: =2*3600+33*60+20 -> 9200 | E12: =SUM(H12:ABF12)-C12 -> -15642.315 | F12: =E12/(D12/3600) -> -6120.9061 | G12: 20 | H12: =IFERROR(__xludf.DUMMYFUNCTION("MAP(OFFSET($H$1,0,0,1,G12*2),LAMBDA(c,IF(ISEVEN(COLUMN(c)),INDIRECT(ADDRESS(REGEXEXTRACT(c,""\d+"")+$B12,14,1,TRUE,""Market"")),INDIRECT(ADDRESS(REGEXEXTRACT(c,""\d+"")+$B12,15,3,,""Market""))*(INDIRECT(ADDRESS(REGEXEXTRACT(c,""\d+"")+$B12,17,3,,""Market"&"""))*(1+$B$27/100)))))"),"Thunderstrike Recipe") -> Thunderstrike Recipe | I12: =IFERROR(__xludf.DUMMYFUNCTION("""COMPUTED_VALUE"""),284.24) -> 284.24 | J12: =IFERROR(__xludf.DUMMYFUNCTION("""COMPUTED_VALUE"""),"Nightfall Sword Recipe") -> Nightfall Sword Recipe | K12: =IFERROR(__xludf.DUMMYFUNCTION("""COMPUTED_VALUE"""),236.84400000000002) -> 236.844 | L12: =IFERROR(__xludf.DUMMYFUNCTION("""COMPUTED_VALUE"""),"Night's Whisper Recipe") -> Night's Whisper Recipe | M12: =IFERROR(__xludf.DUMMYFUNCTION("""COMPUTED_VALUE"""),22.43252) -> 22.43252 | N12: =IFERROR(__xludf.DUMMYFUNCTION("""COMPUTED_VALUE"""),"Eclipse Recipe") -> Eclipse Recipe | O12: =IFERROR(__xludf.DUMMYFUNCTION("""COMPUTED_VALUE"""),26.928) -> 26.928 | P12: =IFERROR(__xludf.DUMMYFUNCTION("""COMPUTED_VALUE"""),"Thundershot Recipe") -> Thundershot Recipe | Q12: =IFERROR(__xludf.DUMMYFUNCTION("""COMPUTED_VALUE"""),187.0) -> 187 | R12: =IFERROR(__xludf.DUMMYFUNCTION("""COMPUTED_VALUE"""),"Nightshade Bow Recipe") -> Nightshade Bow Recipe | S12: =IFERROR(__xludf.DUMMYFUNCTION("""COMPUTED_VALUE"""),428.40000000000003) -> 428.4 | T12: =IFERROR(__xludf.DUMMYFUNCTION("""COMPUTED_VALUE"""),"Voidwalker Cowl Recipe") -> Voidwalker Cowl Recipe | U12: =IFERROR(__xludf.DUMMYFUNCTION("""COMPUTED_VALUE"""),284.24) -> 284.24 | V12: =IFERROR(__xludf.DUMMYFUNCTION("""COMPUTED_VALUE"""),"Lunar Radiance Recipe") -> Lunar Radiance Recipe | W12: =IFERROR(__xludf.DUMMYFUNCTION("""COMPUTED_VALUE"""),244.8) -> 244.8 | X12: =IFERROR(__xludf.DUMMYFUNCTION("""COMPUTED_VALUE"""),"Flameguard Gauntlets Recipe") -> Flameguard Gauntlets Recipe | Y12: =IFERROR(__xludf.DUMMYFUNCTION("""COMPUTED_VALUE"""),209.44) -> 209.44 | Z12: =IFERROR(__xludf.DUMMYFUNCTION("""COMPUTED_VALUE"""),"Stormbreaker Gauntlets Recipe") -> Stormbreaker Gauntlets Recipe | AA12: =IFERROR(__xludf.DUMMYFUNCTION("""COMPUTED_VALUE"""),336.6) -> 336.6 | AB12: =IFERROR(__xludf.DUMMYFUNCTION("""COMPUTED_VALUE"""),"Serpent Scale Recipe") -> Serpent Scale Recipe | AC12: =IFERROR(__xludf.DUMMYFUNCTION("""COMPUTED_VALUE"""),882.64) -> 882.64 | AD12: =IFERROR(__xludf.DUMMYFUNCTION("""COMPUTED_VALUE"""),"Phoenix Soulplate Recipe") -> Phoenix Soulplate Recipe | AE12: =IFERROR(__xludf.DUMMYFUNCTION("""COMPUTED_VALUE"""),1071.0) -> 1071 | AF12: =IFERROR(__xludf.DUMMYFUNCTION("""COMPUTED_VALUE"""),"Voidwalker Striders Recipe") -> Voidwalker Striders Recipe | AG12: =IFERROR(__xludf.DUMMYFUNCTION("""COMPUTED_VALUE"""),411.4) -> 411.4 | AH12: =IFERROR(__xludf.DUMMYFUNCTION("""COMPUTED_VALUE"""),"Stormbreaker Boots Recipe") -> Stormbreaker Boots Recipe | AI12: =IFERROR(__xludf.DUMMYFUNCTION("""COMPUTED_VALUE"""),329.12) -> 329.12 | AJ12: =IFERROR(__xludf.DUMMYFUNCTION("""COMPUTED_VALUE"""),"Moonshadow Guard Recipe") -> Moonshadow Guard Recipe | AK12: =IFERROR(__xludf.DUMMYFUNCTION("""COMPUTED_VALUE"""),112.19999999999999) -> 112.2 | AL12: =IFERROR(__xludf.DUMMYFUNCTION("""COMPUTED_VALUE"""),"Ashenfire Ward Recipe") -> Ashenfire Ward Recipe | AM12: =IFERROR(__xludf.DUMMYFUNCTION("""COMPUTED_VALUE"""),149.6) -> 149.6 | AN12: =IFERROR(__xludf.DUMMYFUNCTION("""COMPUTED_VALUE"""),"Cosmic Tear Recipe") -> Cosmic Tear Recipe | AO12: =IFERROR(__xludf.DUMMYFUNCTION("""COMPUTED_VALUE"""),3712.8) -> 3712.8 | AP12: =IFERROR(__xludf.DUMMYFUNCTION("""COMPUTED_VALUE"""),"Elixir of Life Recipe") -> Elixir of Life Recipe | AQ12: =IFERROR(__xludf.DUMMYFUNCTION("""COMPUTED_VALUE"""),1428.0) -> 1428 | AR12: =IFERROR(__xludf.DUMMYFUNCTION("""COMPUTED_VALUE"""),"Cosmic Tear Recipe (Untradable)") -> Cosmic Tear Recipe (Untradable) | AS12: =IFERROR(__xludf.DUMMYFUNCTION("""COMPUTED_VALUE"""),0.0) -> 0 | AT12: =IFERROR(__xludf.DUMMYFUNCTION("""COMPUTED_VALUE"""),"Elixir of Life Recipe (Untradable)") -> Elixir of Life Recipe (Untradable) | AU12: =IFERROR(__xludf.DUMMYFUNCTION("""COMPUTED_VALUE"""),0.0) -> 0
A13: Eden's Embrace | B13: =B12+G12 -> 185 | C13: 27000 | D13: =2*3600+36*60+40 -> 9400 | E13: =SUM(H13:ABF13)-C13 -> 15475.165 | F13: =E13/(D13/3600) -> 5926.659 | G13: 24 | H13: =IFERROR(__xludf.DUMMYFUNCTION("MAP(OFFSET($H$1,0,0,1,G13*2),LAMBDA(c,IF(ISEVEN(COLUMN(c)),INDIRECT(ADDRESS(REGEXEXTRACT(c,""\d+"")+$B13,14,1,TRUE,""Market"")),INDIRECT(ADDRESS(REGEXEXTRACT(c,""\d+"")+$B13,15,3,,""Market""))*(INDIRECT(ADDRESS(REGEXEXTRACT(c,""\d+"")+$B13,17,3,,""Market"&"""))*(1+$B$27/100)))))"),"Dawnbreaker Sword Recipe") -> Dawnbreaker Sword Recipe | I13: =IFERROR(__xludf.DUMMYFUNCTION("""COMPUTED_VALUE"""),171.35388) -> 171.35388 | J13: =IFERROR(__xludf.DUMMYFUNCTION("""COMPUTED_VALUE"""),"Runeblade Sword Recipe") -> Runeblade Sword Recipe | K13: =IFERROR(__xludf.DUMMYFUNCTION("""COMPUTED_VALUE"""),924.7976879999999) -> 924.79769 | L13: =IFERROR(__xludf.DUMMYFUNCTION("""COMPUTED_VALUE"""),"Duskblade Recipe") -> Duskblade Recipe | M13: =IFERROR(__xludf.DUMMYFUNCTION("""COMPUTED_VALUE"""),11.016) -> 11.016 | N13: =IFERROR(__xludf.DUMMYFUNCTION("""COMPUTED_VALUE"""),"Silent Reaper Recipe") -> Silent Reaper Recipe | O13: =IFERROR(__xludf.DUMMYFUNCTION("""COMPUTED_VALUE"""),219.64) -> 219.64 | P13: =IFERROR(__xludf.DUMMYFUNCTION("""COMPUTED_VALUE"""),"Dawnbreaker Bow Recipe") -> Dawnbreaker Bow Recipe | Q13: =IFERROR(__xludf.DUMMYFUNCTION("""COMPUTED_VALUE"""),416.16) -> 416.16 | R13: =IFERROR(__xludf.DUMMYFUNCTION("""COMPUTED_VALUE"""),"Silverthorn Bow Recipe") -> Silverthorn Bow Recipe | S13: =IFERROR(__xludf.DUMMYFUNCTION("""COMPUTED_VALUE"""),1687.7599999999998) -> 1687.76 | T13: =IFERROR(__xludf.DUMMYFUNCTION("""COMPUTED_VALUE"""),"Ashenfire Crown Recipe") -> Ashenfire Crown Recipe | U13: =IFERROR(__xludf.DUMMYFUNCTION("""COMPUTED_VALUE"""),407.99592) -> 407.99592 | V13: =IFERROR(__xludf.DUMMYFUNCTION("""COMPUTED_VALUE"""),"Nightshade Mask Recipe") -> Nightshade Mask Recipe | W13: =IFERROR(__xludf.DUMMYFUNCTION("""COMPUTED_VALUE"""),376.853688) -> 376.85369 | X13: =IFERROR(__xludf.DUMMYFUNCTION("""COMPUTED_VALUE"""),"Voidrend Gauntlets Recipe") -> Voidrend Gauntlets Recipe | Y13: =IFERROR(__xludf.DUMMYFUNCTION("""COMPUTED_VALUE"""),244.8) -> 244.8 | Z13: =IFERROR(__xludf.DUMMYFUNCTION("""COMPUTED_VALUE"""),"Windrider Recipe") -> Windrider Recipe | AA13: =IFERROR(__xludf.DUMMYFUNCTION("""COMPUTED_VALUE"""),647.3599999999999) -> 647.36 | AB13: =IFERROR(__xludf.DUMMYFUNCTION("""COMPUTED_VALUE"""),"Echosteel Breastplate Recipe") -> Echosteel Breastplate Recipe | AC13: =IFERROR(__xludf.DUMMYFUNCTION("""COMPUTED_VALUE"""),1479.6799999999998) -> 1479.68 | AD13: =IFERROR(__xludf.DUMMYFUNCTION("""COMPUTED_VALUE"""),"Lunarweave Leggings Recipe") -> Lunarweave Leggings Recipe | AE13: =IFERROR(__xludf.DUMMYFUNCTION("""COMPUTED_VALUE"""),330.48) -> 330.48 | AF13: =IFERROR(__xludf.DUMMYFUNCTION("""COMPUTED_VALUE"""),"Nightshade Greaves Recipe") -> Nightshade Greaves Recipe | AG13: =IFERROR(__xludf.DUMMYFUNCTION("""COMPUTED_VALUE"""),439.28) -> 439.28 | AH13: =IFERROR(__xludf.DUMMYFUNCTION("""COMPUTED_VALUE"""),"Voidstep Boots Recipe") -> Voidstep Boots Recipe | AI13: =IFERROR(__xludf.DUMMYFUNCTION("""COMPUTED_VALUE"""),140.148) -> 140.148 | AJ13: =IFERROR(__xludf.DUMMYFUNCTION("""COMPUTED_VALUE"""),"Nightshade Boots Recipe") -> Nightshade Boots Recipe | AK13: =IFERROR(__xludf.DUMMYFUNCTION("""COMPUTED_VALUE"""),1965.1999999999998) -> 1965.2 | AL13: =IFERROR(__xludf.DUMMYFUNCTION("""COMPUTED_VALUE"""),"Runebound Bulwark Recipe") -> Runebound Bulwark Recipe | AM13: =IFERROR(__xludf.DUMMYFUNCTION("""COMPUTED_VALUE"""),61.2) -> 61.2 | AN13: =IFERROR(__xludf.DUMMYFUNCTION("""COMPUTED_VALUE"""),"Shadewalker Bulwark Recipe") -> Shadewalker Bulwark Recipe | AO13: =IFERROR(__xludf.DUMMYFUNCTION("""COMPUTED_VALUE"""),184.95999999999998) -> 184.96 | AP13: =IFERROR(__xludf.DUMMYFUNCTION("""COMPUTED_VALUE"""),"Rune-etched Reeler Recipe") -> Rune-etched Reeler Recipe | AQ13: =IFERROR(__xludf.DUMMYFUNCTION("""COMPUTED_VALUE"""),11934.0) -> 11934 | AR13: =IFERROR(__xludf.DUMMYFUNCTION("""COMPUTED_VALUE"""),"Corestrike Recipe") -> Corestrike Recipe | AS13: =IFERROR(__xludf.DUMMYFUNCTION("""COMPUTED_VALUE"""),11597.400000000001) -> 11597.4 | AT13: =IFERROR(__xludf.DUMMYFUNCTION("""COMPUTED_VALUE"""),"Silvan Splitter Recipe") -> Silvan Splitter Recipe | AU13: =IFERROR(__xludf.DUMMYFUNCTION("""COMPUTED_VALUE"""),5508.0) -> 5508 | AV13: =IFERROR(__xludf.DUMMYFUNCTION("""COMPUTED_VALUE"""),"Potion of the Gods Recipe") -> Potion of the Gods Recipe | AW13: =IFERROR(__xludf.DUMMYFUNCTION("""COMPUTED_VALUE"""),3284.4) -> 3284.4 | AX13: =IFERROR(__xludf.DUMMYFUNCTION("""COMPUTED_VALUE"""),"Eternal Feast Tonic Recipe") -> Eternal Feast Tonic Recipe | AY13: =IFERROR(__xludf.DUMMYFUNCTION("""COMPUTED_VALUE"""),442.68) -> 442.68 | AZ13: =IFERROR(__xludf.DUMMYFUNCTION("""COMPUTED_VALUE"""),"Potion of the Gods Recipe (Untradable)") -> Potion of the Gods Recipe (Untradable) | BA13: =IFERROR(__xludf.DUMMYFUNCTION("""COMPUTED_VALUE"""),0.0) -> 0 | BB13: =IFERROR(__xludf.DUMMYFUNCTION("""COMPUTED_VALUE"""),"Eternal Feast Tonic Recipe (Untradable)") -> Eternal Feast Tonic Recipe (Untradable) | BC13: =IFERROR(__xludf.DUMMYFUNCTION("""COMPUTED_VALUE"""),0.0) -> 0
A14: Arboreal Labyrinth | B14: =B13+G13 -> 209 | C14: 30000 | D14: =2*3600+40*60+0 -> 9600 | E14: =SUM(H14:ABF14)-C14 -> -3699.912 | F14: =E14/(D14/3600) -> -1387.467 | G14: 23 | H14: =IFERROR(__xludf.DUMMYFUNCTION("MAP(OFFSET($H$1,0,0,1,G14*2),LAMBDA(c,IF(ISEVEN(COLUMN(c)),INDIRECT(ADDRESS(REGEXEXTRACT(c,""\d+"")+$B14,14,1,TRUE,""Market"")),INDIRECT(ADDRESS(REGEXEXTRACT(c,""\d+"")+$B14,15,3,,""Market""))*(INDIRECT(ADDRESS(REGEXEXTRACT(c,""\d+"")+$B14,17,3,,""Market"&"""))*(1+$B$27/100)))))"),"Starshard Recipe") -> Starshard Recipe | I14: =IFERROR(__xludf.DUMMYFUNCTION("""COMPUTED_VALUE"""),673.2) -> 673.2 | J14: =IFERROR(__xludf.DUMMYFUNCTION("""COMPUTED_VALUE"""),"Phoenix Requiem Recipe") -> Phoenix Requiem Recipe | K14: =IFERROR(__xludf.DUMMYFUNCTION("""COMPUTED_VALUE"""),2427.5999999999995) -> 2427.6 | L14: =IFERROR(__xludf.DUMMYFUNCTION("""COMPUTED_VALUE"""),"Ghostwalker Recipe") -> Ghostwalker Recipe | M14: =IFERROR(__xludf.DUMMYFUNCTION("""COMPUTED_VALUE"""),48.348000000000006) -> 48.348 | N14: =IFERROR(__xludf.DUMMYFUNCTION("""COMPUTED_VALUE"""),"Silvermist Recipe") -> Silvermist Recipe | O14: =IFERROR(__xludf.DUMMYFUNCTION("""COMPUTED_VALUE"""),203.99999999999997) -> 204 | P14: =IFERROR(__xludf.DUMMYFUNCTION("""COMPUTED_VALUE"""),"Starshower Recipe") -> Starshower Recipe | Q14: =IFERROR(__xludf.DUMMYFUNCTION("""COMPUTED_VALUE"""),918.0000000000001) -> 918 | R14: =IFERROR(__xludf.DUMMYFUNCTION("""COMPUTED_VALUE"""),"Bloodmoon Bow Recipe") -> Bloodmoon Bow Recipe | S14: =IFERROR(__xludf.DUMMYFUNCTION("""COMPUTED_VALUE"""),5099.999999999999) -> 5100 | T14: =IFERROR(__xludf.DUMMYFUNCTION("""COMPUTED_VALUE"""),"Verdant Guardian Helm Recipe") -> Verdant Guardian Helm Recipe | U14: =IFERROR(__xludf.DUMMYFUNCTION("""COMPUTED_VALUE"""),1101.6000000000001) -> 1101.6 | V14: =IFERROR(__xludf.DUMMYFUNCTION("""COMPUTED_VALUE"""),"Glimmersteel Helm Recipe") -> Glimmersteel Helm Recipe | W14: =IFERROR(__xludf.DUMMYFUNCTION("""COMPUTED_VALUE"""),611.9999999999999) -> 612 | X14: =IFERROR(__xludf.DUMMYFUNCTION("""COMPUTED_VALUE"""),"Lunarweave Gloves Recipe") -> Lunarweave Gloves Recipe | Y14: =IFERROR(__xludf.DUMMYFUNCTION("""COMPUTED_VALUE"""),734.4000000000001) -> 734.4 | Z14: =IFERROR(__xludf.DUMMYFUNCTION("""COMPUTED_VALUE"""),"Bloodforged Gauntlets Recipe") -> Bloodforged Gauntlets Recipe | AA14: =IFERROR(__xludf.DUMMYFUNCTION("""COMPUTED_VALUE"""),1530.0) -> 1530 | AB14: =IFERROR(__xludf.DUMMYFUNCTION("""COMPUTED_VALUE"""),"Grasps of Protection Recipe") -> Grasps of Protection Recipe | AC14: =IFERROR(__xludf.DUMMYFUNCTION("""COMPUTED_VALUE"""),1050.6) -> 1050.6 | AD14: =IFERROR(__xludf.DUMMYFUNCTION("""COMPUTED_VALUE"""),"Guardian's Valor Recipe") -> Guardian's Valor Recipe | AE14: =IFERROR(__xludf.DUMMYFUNCTION("""COMPUTED_VALUE"""),2203.2000000000003) -> 2203.2 | AF14: =IFERROR(__xludf.DUMMYFUNCTION("""COMPUTED_VALUE"""),"Verdant Chainmail Recipe") -> Verdant Chainmail Recipe | AG14: =IFERROR(__xludf.DUMMYFUNCTION("""COMPUTED_VALUE"""),1223.9999999999998) -> 1224 | AH14: =IFERROR(__xludf.DUMMYFUNCTION("""COMPUTED_VALUE"""),"Runebound Shinplates Recipe") -> Runebound Shinplates Recipe | AI14: =IFERROR(__xludf.DUMMYFUNCTION("""COMPUTED_VALUE"""),612.0) -> 612 | AJ14: =IFERROR(__xludf.DUMMYFUNCTION("""COMPUTED_VALUE"""),"Glimmersteel Pathguards Recipe") -> Glimmersteel Pathguards Recipe | AK14: =IFERROR(__xludf.DUMMYFUNCTION("""COMPUTED_VALUE"""),1121.9999999999998) -> 1122 | AL14: =IFERROR(__xludf.DUMMYFUNCTION("""COMPUTED_VALUE"""),"Ashenfire Boots Recipe") -> Ashenfire Boots Recipe | AM14: =IFERROR(__xludf.DUMMYFUNCTION("""COMPUTED_VALUE"""),489.6) -> 489.6 | AN14: =IFERROR(__xludf.DUMMYFUNCTION("""COMPUTED_VALUE"""),"Glimmersteel Boots Recipe") -> Glimmersteel Boots Recipe | AO14: =IFERROR(__xludf.DUMMYFUNCTION("""COMPUTED_VALUE"""),2039.9999999999998) -> 2040 | AP14: =IFERROR(__xludf.DUMMYFUNCTION("""COMPUTED_VALUE"""),"Bloodbane Barrier Recipe") -> Bloodbane Barrier Recipe | AQ14: =IFERROR(__xludf.DUMMYFUNCTION("""COMPUTED_VALUE"""),88.74000000000001) -> 88.74 | AR14: =IFERROR(__xludf.DUMMYFUNCTION("""COMPUTED_VALUE"""),"Stormbringer Buckler Recipe") -> Stormbringer Buckler Recipe | AS14: =IFERROR(__xludf.DUMMYFUNCTION("""COMPUTED_VALUE"""),407.99999999999994) -> 408 | AT14: =IFERROR(__xludf.DUMMYFUNCTION("""COMPUTED_VALUE"""),"Divine Nectar Recipe") -> Divine Nectar Recipe | AU14: =IFERROR(__xludf.DUMMYFUNCTION("""COMPUTED_VALUE"""),856.8) -> 856.8 | AV14: =IFERROR(__xludf.DUMMYFUNCTION("""COMPUTED_VALUE"""),"Fallen Star Essence Recipe") -> Fallen Star Essence Recipe | AW14: =IFERROR(__xludf.DUMMYFUNCTION("""COMPUTED_VALUE"""),2856.0) -> 2856 | AX14: =IFERROR(__xludf.DUMMYFUNCTION("""COMPUTED_VALUE"""),"Divine Nectar Recipe (Untradable)") -> Divine Nectar Recipe (Untradable) | AY14: =IFERROR(__xludf.DUMMYFUNCTION("""COMPUTED_VALUE"""),0.0) -> 0 | AZ14: =IFERROR(__xludf.DUMMYFUNCTION("""COMPUTED_VALUE"""),"Fallen Star Essence Recipe (Untradable)") -> Fallen Star Essence Recipe (Untradable) | BA14: =IFERROR(__xludf.DUMMYFUNCTION("""COMPUTED_VALUE"""),0.0) -> 0
